2022-06-03 07:10:49,535 |                  flt |    ERROR | Traceback (most recent call last):
  File "/usr/local/lib/python3.8/dist-packages/foliant/cli/make.py", line 100, in get_config
    config = Parser(project_path, config_file_name, self.logger, quiet).parse()
  File "/usr/local/lib/python3.8/dist-packages/foliant/config/base.py", line 38, in parse
    config = {**self._defaults, **load(config_file, Loader)}
  File "/usr/local/lib/python3.8/dist-packages/yaml/__init__.py", line 114, in load
    return loader.get_single_data()
  File "/usr/local/lib/python3.8/dist-packages/yaml/constructor.py", line 49, in get_single_data
    node = self.get_single_node()
  File "/usr/local/lib/python3.8/dist-packages/yaml/composer.py", line 36, in get_single_node
    document = self.compose_document()
  File "/usr/local/lib/python3.8/dist-packages/yaml/composer.py", line 55, in compose_document
    node = self.compose_node(None, None)
  File "/usr/local/lib/python3.8/dist-packages/yaml/composer.py", line 84, in compose_node
    node = self.compose_mapping_node(anchor)
  File "/usr/local/lib/python3.8/dist-packages/yaml/composer.py", line 133, in compose_mapping_node
    item_value = self.compose_node(node, item_key)
  File "/usr/local/lib/python3.8/dist-packages/yaml/composer.py", line 82, in compose_node
    node = self.compose_sequence_node(anchor)
  File "/usr/local/lib/python3.8/dist-packages/yaml/composer.py", line 110, in compose_sequence_node
    while not self.check_event(SequenceEndEvent):
  File "/usr/local/lib/python3.8/dist-packages/yaml/parser.py", line 98, in check_event
    self.current_event = self.state()
  File "/usr/local/lib/python3.8/dist-packages/yaml/parser.py", line 392, in parse_block_sequence_entry
    raise ParserError("while parsing a block collection", self.marks[-1],
yaml.parser.ParserError: while parsing a block collection
  in "foliant.yml", line 4, column 4
expected <block end>, but found '<block sequence start>'
  in "foliant.yml", line 5, column 5

During handling of the above exception, another exception occurred:

Traceback (most recent call last):
  File "/usr/local/lib/python3.8/dist-packages/foliant/utils.py", line 158, in spinner
    yield
  File "/usr/local/lib/python3.8/dist-packages/foliant/cli/make.py", line 108, in get_config
    raise RuntimeError(f'Invalid config: {exception}')
RuntimeError: Invalid config: while parsing a block collection
  in "foliant.yml", line 4, column 4
expected <block end>, but found '<block sequence start>'
  in "foliant.yml", line 5, column 5

2022-06-03 07:10:49,538 |                  flt | CRITICAL | Config parsing failed.
